Workbook

Sheet 01_Cover
B2: Inter IKEA Group
B3: Financial Performance Analysis
B4: FY23–FY25
B6: Prepared by | C6: Neha R K
B7: Project type | C7: Independent Portfolio Case Study
B8: Reporting currency | C8: EUR millions
B9: Financial year-end | C9: 46265
B10: Status | C10: In Progress
B16: *This independent educational case study uses publicly available information. It is not affiliated with or endorsed by Inter IKEA Group.

Sheet 02_Source_Register
A1: Source ID | B1: Report | C1: Year | D1: Pages | E1: Status
A2: AR-23 | B2: Annual Report | C2: FY23 | D2: TBD | E2: Pending
A3: AR-24 | B3: Annual Report | C3: FY24 | D3: TBD | E3: Pending
A4: AR-25 | B4: Annual Report | C4: FY25 | D4: TBD | E4: Pending

Sheet 03_Raw_Income_Statement
A1: Line Item | B1: FY23 | C1: FY24 | D1: FY25 | E1: FY23 Page | F1: FY24 Page | G1: FY25 Page | H1: Notes
A2: Net turnover | B2: 29109 | C2: 26596 | D2: 26183 | E2: 15 | F2: 15 | G2: 15
A3: Change in inventory of finished goods | B3: -152 | C3: -82 | D3: 107 | E3: 15 | F3: 15 | G3: 15
A4: Other operating income | B4: 106 | C4: 24 | D4: 16 | E4: 15 | F4: 15 | G4: 15
A5: Total operating income | B5: 29063 | C5: 26538 | D5: 26306 | E5: 15 | F5: 15 | G5: 15 | H5: Note 17
A6: Cost of raw materials and consumables | B6: 23824 | C6: 21048 | D6: 21328 | E6: 15 | F6: 15 | G6: 15
A7: Cost of outsourced work and other external costs | B7: 239 | C7: 227 | D7: 239 | E7: 15 | F7: 15 | G7: 15
A8: Salaries and wages | B8: 999 | C8: 978 | D8: 1099 | E8: 15 | F8: 15 | G8: 15
A9: Social charges | B9: 236 | C9: 230 | D9: 259 | E9: 15 | F9: 15 | G9: 15
A10: Pension expenses | B10: 98 | C10: 102 | D10: 116 | E10: 15 | F10: 15 | G10: 15
A11: Depreciation and amortisation | B11: 460 | C11: 462 | D11: 510 | E11: 15 | F11: 15 | G11: 15
A12: Impairments of fixed assets | B12: 0 | C12: 27 | D12: -2 | E12: 15 | F12: 15 | G12: 15
A13: Other operating expenses | B13: 961 | C13: 1125 | D13: 1032 | E13: 15 | F13: 15 | G13: 15
A14: Total operating expenses | B14: 26817 | C14: 24199 | D14: 24581 | E14: 15 | F14: 15 | G14: 15
A15: Operating result | B15: 2246 | C15: 2339 | D15: 1725 | E15: 15 | F15: 15 | G15: 15
A16: Financial income | B16: 211 | C16: 400 | D16: 273 | E16: 15 | F16: 15 | G16: 15 | H16: Note 19
A17: Financial expense | B17: 511 | C17: 74 | D17: 46 | E17: 15 | F17: 15 | G17: 15
A18: Financial income and expense | B18: -300 | C18: 326 | D18: 227 | E18: 15 | F18: 15 | G18: 15
A19: Result before tax | B19: 1946 | C19: 2665 | D19: 1952 | E19: 15 | F19: 15 | G19: 15
A20: Income tax | B20: 307 | C20: 466 | D20: 415 | E20: 15 | F20: 15 | G20: 15 | H20: Note 20
A21: Share of results from participating interests | B21: 0 | C21: 0 | D21: -41 | E21: 15 | F21: 15 | G21: 15
A22: Net result | B22: 1639 | C22: 2199 | D22: 1496 | E22: 15 | F22: 15 | G22: 15

Sheet 04_Raw_Balance_Sheet
A1: Line Item | B1: FY23 | C1: FY24 | D1: FY25 | E1: FY23 Page | F1: FY24 Page | G1: FY25 Page | H1: Notes
A2: Fixed Assets
A3: Intangible Fixed Assets | B3: 9094 | C3: 8821 | D3: 8899 | E3: 14 | F3: 14 | G3: 14 | H3: Note 4
A4: Tangible Fixed Assets | B4: 1742 | C4: 1794 | D4: 1952 | E4: 14 | F4: 14 | G4: 14 | H4: Note 5
A5: Financial Fixed Assets | B5: 337 | C5: 303 | D5: 285 | E5: 14 | F5: 14 | G5: 14 | H5: Note 6
A6: Total Fixed Assets | B6: 11173 | C6: 10918 | D6: 11136 | E6: 14 | F6: 14 | G6: 14 | H6: Reported Total
A8: Current Assets | E8: 14 | F8: 14 | G8: 14
A9: Inventories | B9: 4772 | C9: 4108 | D9: 4832 | E9: 14 | F9: 14 | G9: 14 | H9: Note 7
A10: Trade and Other Receivables | B10: 6887 | C10: 3282 | D10: 3212 | E10: 14 | F10: 14 | G10: 14 | H10: Note 8
A11: Cash and Cash Equivalents | B11: 169 | C11: 4164 | D11: 2937 | E11: 14 | F11: 14 | G11: 14 | H11: Note 9
A12: Total Current Assets | B12: 11828 | C12: 11554 | D12: 10981 | E12: 14 | F12: 14 | G12: 14
A14: TOTAL ASSETS | B14: 23001 | C14: 22472 | D14: 22117 | E14: 14 | F14: 14 | G14: 14
E15: 14 | F15: 14 | G15: 14
A16: Group Equity | B16: 17758 | C16: 19212 | D16: 18815 | E16: 14 | F16: 14 | G16: 14 | H16: Note 10
A17: Provisions | B17: 118 | C17: 94 | D17: 142 | E17: 14 | F17: 14 | G17: 14 | H17: Note 11
A18: Non-current Liabilities | B18: 86 | C18: 84 | D18: 72 | E18: 14 | F18: 14 | G18: 14 | H18: Note 13
A19: Current Liabilities | B19: 5039 | C19: 3082 | D19: 3088 | E19: 14 | F19: 14 | G19: 14 | H19: Note 14
A20: TOTAL EQUITY AND LIABILITIES | B20: 23001 | C20: 22472 | D20: 22117 | E20: 14 | F20: 14 | G20: 14 | H20: Reported Total

Sheet 05_Raw_Cash_Flow
A1: Line Item | B1: FY23 | C1: FY24 | D1: FY25 | E1: FY23 Page | F1: FY24 Page | G1: FY25 Page | H1: Notes
A2: Operating Result | B2: 2246 | C2: 2339 | D2: 1725 | E2: 16 | F2: 16 | G2: 16 | H2: Reported Total
A3: Depreciation / Amortisation | B3: 460 | C3: 462 | D3: 510 | E3: 16 | F3: 16 | G3: 16 | H3: Note 4,5
A4: Impairments | B4: 0 | C4: 27 | D4: -2 | E4: 16 | F4: 16 | G4: 16 | H4: Note 4,5
A5: Other Value Adjustments | B5: 64 | C5: -27 | D5: 15 | E5: 16 | F5: 16 | G5: 16 | H5: Note 4,5
A6: Changes in Provisions | B6: -6 | C6: -24 | D6: 48 | E6: 16 | F6: 16 | G6: 16 | H6: Note 11
A7: Changes in Financial Fixed Assets | B7: -3 | C7: 0 | D7: 0 | E7: 16 | F7: 16 | G7: 16 | H7: Note 6
A8: Changes in Working Capital | B8: 1243 | C8: 1715 | D8: -788 | E8: 16 | F8: 16 | G8: 16 | H8: Working Capital
A9: Cash Flow from Business Operations | B9: 4004 | C9: 4492 | D9: 1508 | E9: 16 | F9: 16 | G9: 16 | H9: Reported Total
A10: Interest Received | B10: 93 | C10: 179 | D10: 110 | E10: 16 | F10: 16 | G10: 16 | H10: Finance Income
A11: Interest Paid | B11: -507 | C11: -50 | D11: -9 | E11: 16 | F11: 16 | G11: 16 | H11: Finance Expense
A12: Income Tax Paid | B12: -299 | C12: -320 | D12: -362 | E12: 16 | F12: 16 | G12: 16 | H12: Tax Paid
A13: Cash Flow from Operating Activities | B13: 3291 | C13: 4301 | D13: 1247 | E13: 16 | F13: 16 | G13: 16 | H13: Reported Total
A14: Investments In:
A15: Intangible Fixed Assets | B15: 0 | C15: -2 | D15: -295 | E15: 16 | F15: 16 | G15: 16 | H15: Note 4
A16: Tangible Fixed Assets | B16: -347 | C16: -245 | D16: -382 | E16: 16 | F16: 16 | G16: 16 | H16: Note 5
A17: Acquisition of Companies | B17: 0 | C17: -16 | D17: -27 | E17: 16 | F17: 16 | G17: 16 | H17: Note 6
A18: Disposals Of:
A19: Tangible Fixed Assets | B19: 7 | C19: 19 | D19: 11 | E19: 16 | F19: 16 | G19: 16 | H19: Note 5
A20: Issuance of Loans Receivable | B20: 0 | C20: -20 | D20: -41 | E20: 16 | F20: 16 | G20: 16 | H20: Note 6
A21: Repayment of Loans Receivable | B21: -52 | C21: 8 | D21: 77 | E21: 16 | F21: 16 | G21: 16 | H21: Note 6
A22: Cash Flow from Investing Activities | B22: -392 | C22: -256 | D22: -657 | E22: 16 | F22: 16 | G22: 16 | H22: Reported Total
A23: Repayment of Long-term Financing | B23: -27 | C23: -2 | D23: -12 | E23: 16 | F23: 16 | G23: 16 | H23: Note 13
A24: Short-term Financing | B24: -3867 | C24: 952 | D24: 2 | E24: 16 | F24: 16 | G24: 16 | H24: Note 14
A25: Dividend Paid | B25: -1850 | C25: -1000 | D25: -1800 | E25: 16 | F25: 16 | G25: 16 | H25: Note 10
A26: Capital Contribution | B26: 2846 | C26: 0 | D26: 0 | E26: 16 | F26: 16 | G26: 16 | H26: Note 10
A27: Cash Flow from Financing Activities | B27: -2898 | C27: -50 | D27: -1810 | E27: 16 | F27: 16 | G27: 16 | H27: Reported Total
A28: Net Cash Flow | B28: 1 | C28: 3995 | D28: -1220 | E28: 16 | F28: 16 | G28: 16 | H28: Reported Total
A29: Exchange Rate & Translation Differences | B29: -16 | C29: 0 | D29: -7 | E29: 16 | F29: 16 | G29: 16 | H29: Reported
A30: Changes in Cash & Cash Equivalents | B30: -15 | C30: 3995 | D30: -1227 | E30: 16 | F30: 16 | G30: 16 | H30: Reported Total
... A33: Net Movement in Cash | B33: -15 | C33: 3995 | D33: -1227 | E33: 16 | F33: 16 | G33: 16 | H33: Reported Total

Sheet 06_Standardized_P&L
A1: Line Item | B1: FY23 | C1: FY24 | D1: FY25 | E1: FY23 Page | F1: FY24 Page | G1: FY25 Page | H1: Notes
A2: Operating Income | B2: ='03_Raw_Income_Statement'!B5 -> 29063 | C2: ='03_Raw_Income_Statement'!C5 -> 26538 | D2: ='03_Raw_Income_Statement'!D5 -> 26306 | E2: 15 | F2: 15 | G2: 15 | H2: Note 17
A3: Cost of Raw Materials | B3: ='03_Raw_Income_Statement'!B6 -> 23824 | C3: ='03_Raw_Income_Statement'!C6 -> 21048 | D3: ='03_Raw_Income_Statement'!D6 -> 21328 | E3: 15 | F3: 15 | G3: 15
A4: Personnel Expenses | B4: ='03_Raw_Income_Statement'!B8+'03_Raw_Income_Statement'!B9+'03_Raw_Income_Statement'!B10 -> 1333 | C4: ='03_Raw_Income_Statement'!C8+'03_Raw_Income_Statement'!C9+'03_Raw_Income_Statement'!C10 -> 1310 | D4: ='03_Raw_Income_Statement'!D8+'03_Raw_Income_Statement'!D9+'03_Raw_Income_Statement'!D10 -> 1474 | E4: 15 | F4: 15 | G4: 15 | H4: Derived (Salaries + Social Charges + Pension) (only in the standardized sheet)
A5: Depreciation & Amortisation | B5: ='03_Raw_Income_Statement'!B11 -> 460 | C5: ='03_Raw_Income_Statement'!C11 -> 462 | D5: ='03_Raw_Income_Statement'!D11 -> 510 | E5: 15 | F5: 15 | G5: 15
A6: Other Operating Expenses | B6: ='03_Raw_Income_Statement'!B13+'03_Raw_Income_Statement'!B12+'03_Raw_Income_Statement'!B7 -> 1200 | C6: ='03_Raw_Income_Statement'!C13+'03_Raw_Income_Statement'!C12+'03_Raw_Income_Statement'!C7 -> 1379 | D6: ='03_Raw_Income_Statement'!D13+'03_Raw_Income_Statement'!D12+'03_Raw_Income_Statement'!D7 -> 1269 | E6: 15 | F6: 15 | G6: 15
A7: Operating Result | B7: =B2-(B3+B4+B5+B6) -> 2246 | C7: =C2-(C3+C4+C5+C6) -> 2339 | D7: =D2-(D3+D4+D5+D6) -> 1725 | E7: 15 | F7: 15 | G7: 15
A8: Financial Income | B8: ='03_Raw_Income_Statement'!B16 -> 211 | C8: ='03_Raw_Income_Statement'!C16 -> 400 | D8: ='03_Raw_Income_Statement'!D16 -> 273 | E8: 15 | F8: 15 | G8: 15 | H8: Note 19
A9: Financial Expenses | B9: ='03_Raw_Income_Statement'!B17 -> 511 | C9: ='03_Raw_Income_Statement'!C17 -> 74 | D9: ='03_Raw_Income_Statement'!D17 -> 46 | E9: 15 | F9: 15 | G9: 15
A10: Profit Before Tax | B10: =B7-B9+B8 -> 1946 | C10: =C7-C9+C8 -> 2665 | D10: =D7-D9+D8 -> 1952 | E10: 15 | F10: 15 | G10: 15
A11: Income Tax | B11: ='03_Raw_Income_Statement'!B20 -> 307 | C11: ='03_Raw_Income_Statement'!C20 -> 466 | D11: ='03_Raw_Income_Statement'!D20 -> 415 | E11: 15 | F11: 15 | G11: 15 | H11: Note 20
A12: Net Profit | B12: =B10-B11 -> 1639 | C12: =C10-C11 -> 2199 | D12: =D10-D11+'03_Raw_Income_Statement'!D21 -> 1496 | E12: 15 | F12: 15 | G12: 15 | H12: Reported Total

Sheet  07_Standardized_Balance_Sheet
A1: Line Item | B1: FY23 | C1: FY24 | D1: FY25 | E1: FY23 Page | F1: FY24 Page | G1: FY25 Page | H1: Notes
A2: Non-current Assets
A3: Intangible Assets | B3: 9094 | C3: 8821 | D3: 8899 | E3: 14 | F3: 14 | G3: 14 | H3: Note 4
A4: Property, Plant & Equipment (Tangible Assets) | B4: 1742 | C4: 1794 | D4: 1952 | E4: 14 | F4: 14 | G4: 14 | H4: Note 5
A5: Financial Assets | B5: 337 | C5: 303 | D5: 285 | E5: 14 | F5: 14 | G5: 14 | H5: Note 6
A6: Total Non-current Assets | B6: =SUM(B3:B5) -> 11173 | C6: =SUM(C3:C5) -> 10918 | D6: =SUM(D3:D5) -> 11136 | E6: 14 | F6: 14 | G6: 14 | H6: Reported Total
A8: Current Assets
A9: Inventory | B9: 4772 | C9: 4108 | D9: 4832 | E9: 14 | F9: 14 | G9: 14 | H9: Note 7
A10: Trade & Other Receivables | B10: 6887 | C10: 3282 | D10: 3212 | E10: 14 | F10: 14 | G10: 14 | H10: Note 8
A11: Cash & Cash Equivalents | B11: 169 | C11: 4164 | D11: 2937 | E11: 14 | F11: 14 | G11: 14 | H11: Note 9
A12: Total Current Assets | B12: =SUM(B9:B11) -> 11828 | C12: =SUM(C9:C11) -> 11554 | D12: =SUM(D9:D11) -> 10981 | E12: 14 | F12: 14 | G12: 14 | H12: Reported Total
A14: TOTAL ASSETS | B14: =SUM(B6+B12) -> 23001 | C14: =SUM(C6+C12) -> 22472 | D14: =SUM(D6+D12) -> 22117 | E14: 14 | F14: 14 | G14: 14 | H14: Reported Total
A16: Equity & Liabilities | E16: 14 | F16: 14 | G16: 14
A17: Equity | B17: 17758 | C17: 19212 | D17: 18815 | E17: 14 | F17: 14 | G17: 14 | H17: Note 10
A18: Provisions | B18: 118 | C18: 94 | D18: 142 | E18: 14 | F18: 14 | G18: 14 | H18: Note 11
A19: Non-current Liabilities | B19: 86 | C19: 84 | D19: 72 | E19: 14 | F19: 14 | G19: 14 | H19: Note 12
A20: Current Liabilities | B20: 5039 | C20: 3082 | D20: 3088 | E20: 14 | F20: 14 | G20: 14 | H20: Note 13
A21: Total Liabilities | B21: =B18+B19+B20 -> 5243 | C21: =C18+C19+C20 -> 3260 | D21: =D18+D19+D20 -> 3302 | E21: 14 | F21: 14 | G21: 14 | H21: Reported Total
A22: TOTAL EQUITY & LIABILITIES | B22: =B17+B21 -> 23001 | C22: =C17+C21 -> 22472 | D22: =D17+D21 -> 22117 | E22: 14 | F22: 14 | G22: 14 | H22: Reported Total

Sheet 08_Standardized_Cash_Flow
A1: Line Item | B1: FY23 | C1: FY24 | D1: FY25
A2: Operating Activities
A3: Cash Flow from Operating Activities | B3: 3291 | C3: 4301 | D3: 1247
A5: Investing Activities
A6: Capital Expenditure (Intangible + Tangible Assets) | B6: ='05_Raw_Cash_Flow'!B15+'05_Raw_Cash_Flow'!B16 -> -347 | C6: ='05_Raw_Cash_Flow'!C15+'05_Raw_Cash_Flow'!C16 -> -247 | D6: ='05_Raw_Cash_Flow'!D15+'05_Raw_Cash_Flow'!D16 -> -677
A7: Acquisition of Companies | B7: 0 | C7: -16 | D7: -27
A8: Disposal of Assets | B8: 7 | C8: 19 | D8: 11
A9: Net Loans Receivable | B9: ='05_Raw_Cash_Flow'!B21+'05_Raw_Cash_Flow'!B20 -> -52 | C9: ='05_Raw_Cash_Flow'!C21+'05_Raw_Cash_Flow'!C20 -> -12 | D9: ='05_Raw_Cash_Flow'!D21+'05_Raw_Cash_Flow'!D20 -> 36
A10: Cash Flow from Investing Activities | B10: =SUM(B6:B9) -> -392 | C10: =SUM(C6:C9) -> -256 | D10: =SUM(D6:D9) -> -657
A12: Financing Activities
A13: Long-term Financing | B13: -27 | C13: -2 | D13: -12
A14: Short-term Financing | B14: -3867 | C14: 952 | D14: 2
A15: Dividend Paid | B15: -1850 | C15: -1000 | D15: -1800
A16: Capital Contribution | B16: 2846 | C16: 0 | D16: 0
A17: Cash Flow from Financing Activities | B17: =SUM(B13:B16) -> -2898 | C17: =SUM(C13:C16) -> -50 | D17: =SUM(D13:D16) -> -1810
A19: Net Cash Flow | B19: =B3+B10+B17 -> 1 | C19: =C3+C10+C17 -> 3995 | D19: =D3+D10+D17 -> -1220
A20: Exchange Rate Differences | B20: -16 | C20: 0 | D20: -7
A21: Net Change in Cash | B21: =B19+B20 -> -15 | C21: =C19+C20 -> 3995 | D21: =D19+D20 -> -1227
A22: Cash at Beginning of Year | B22: 184 | C22: 169 | D22: 4164
A23: Cash at End of Year | B23: =B21+B22 -> 169 | C23: =C21+C22 -> 4164 | D23: =D21+D22 -> 2937

Sheet 09_Ratio_Analysis
A1: Ratio | B1: Formula | C1: FY23 | D1: FY24 | E1: FY25 | F1: FY23→FY25 Change
A2: Gross Margin | B2: (Net Turnover - Cost of Raw Materials)÷ Net Turnover | C2: =(Table2[[#This Row],[FY23]]-'03_Raw_Income_Statement'!B6)/Table2[[#This Row],[FY23]] -> 0.18155897 | D2: =(Table2[[#This Row],[FY24]]-'03_Raw_Income_Statement'!C6)/Table2[[#This Row],[FY24]] -> 0.2086028 | E2: =(Table2[[#This Row],[FY25]]-'03_Raw_Income_Statement'!D6)/Table2[[#This Row],[FY25]] -> 0.18542566 | F2: =Table3[[#This Row],[FY25]]/Table3[[#This Row],[FY23]]-1 -> 0.021297157
A3: Operating Margin | B3: Operating Result ÷ Operating Income | C3: ='06_Standardized_P&L'!B7/'06_Standardized_P&L'!B2 -> 0.077280391 | D3: ='06_Standardized_P&L'!C7/'06_Standardized_P&L'!C2 -> 0.088137765 | E3: ='06_Standardized_P&L'!D7/'06_Standardized_P&L'!D2 -> 0.065574394 | F3: =Table3[[#This Row],[FY25]]/Table3[[#This Row],[FY23]]-1 -> -0.15147435
A4: Net Profit Margin | B4: Net Profit ÷ Operating Income | C4: ='06_Standardized_P&L'!B12/'06_Standardized_P&L'!B2 -> 0.056394729 | D4: ='06_Standardized_P&L'!C12/'06_Standardized_P&L'!C2 -> 0.082862311 | E4: ='06_Standardized_P&L'!D12/'06_Standardized_P&L'!D2 -> 0.056869155 | F4: =Table3[[#This Row],[FY25]]/Table3[[#This Row],[FY23]]-1 -> 0.008412606
A5: Current Ratio | B5: Current Assets ÷ Current Liabilities | C5: =' 07_Standardized_Balance_Sheet'!B12/' 07_Standardized_Balance_Sheet'!B20 -> 2.3472911 | D5: =' 07_Standardized_Balance_Sheet'!C12/' 07_Standardized_Balance_Sheet'!C20 -> 3.7488644 | E5: =' 07_Standardized_Balance_Sheet'!D12/' 07_Standardized_Balance_Sheet'!D20 -> 3.5560233 | F5: =Table3[[#This Row],[FY25]]/Table3[[#This Row],[FY23]]-1 -> 0.51494771
A6: Quick Ratio | B6: (Current Assets − Inventory) ÷ Current Liabilities | C6: =(' 07_Standardized_Balance_Sheet'!B12-' 07_Standardized_Balance_Sheet'!B9)/' 07_Standardized_Balance_Sheet'!B20 -> 1.4002778 | D6: =(' 07_Standardized_Balance_Sheet'!C12-' 07_Standardized_Balance_Sheet'!C9)/' 07_Standardized_Balance_Sheet'!C20 -> 2.4159637 | E6: =(' 07_Standardized_Balance_Sheet'!D12-' 07_Standardized_Balance_Sheet'!D9)/' 07_Standardized_Balance_Sheet'!D20 -> 1.9912565 | F6: =Table3[[#This Row],[FY25]]/Table3[[#This Row],[FY23]]-1 -> 0.42204385
A7: Debt to Equity | B7: Total Liabilities ÷ Equity | C7: =' 07_Standardized_Balance_Sheet'!B21/' 07_Standardized_Balance_Sheet'!B17 -> 0.29524721 | D7: =' 07_Standardized_Balance_Sheet'!C21/' 07_Standardized_Balance_Sheet'!C17 -> 0.16968561 | E7: =' 07_Standardized_Balance_Sheet'!D21/' 07_Standardized_Balance_Sheet'!D17 -> 0.17549827 | F7: =Table3[[#This Row],[FY25]]/Table3[[#This Row],[FY23]]-1 -> -0.40558872
A8: Equity Ratio | B8: Equity ÷ Total Assets | C8: =' 07_Standardized_Balance_Sheet'!B17/' 07_Standardized_Balance_Sheet'!B14 -> 0.77205339 | D8: =' 07_Standardized_Balance_Sheet'!C17/' 07_Standardized_Balance_Sheet'!C14 -> 0.85493058 | E8: =' 07_Standardized_Balance_Sheet'!D17/' 07_Standardized_Balance_Sheet'!D14 -> 0.85070308 | F8: =Table3[[#This Row],[FY25]]/Table3[[#This Row],[FY23]]-1 -> 0.10187079
A9: ROA | B9: Net Profit ÷ Total Assets | C9: ='06_Standardized_P&L'!B12/' 07_Standardized_Balance_Sheet'!B14 -> 0.071257771 | D9: ='06_Standardized_P&L'!C12/' 07_Standardized_Balance_Sheet'!C14 -> 0.097855109 | E9: ='06_Standardized_P&L'!D12/' 07_Standardized_Balance_Sheet'!D14 -> 0.067640277 | F9: =Table3[[#This Row],[FY25]]/Table3[[#This Row],[FY23]]-1 -> -0.050766318
A10: ROE | B10: Net Profit ÷ Equity | C10: ='06_Standardized_P&L'!B12/' 07_Standardized_Balance_Sheet'!B17 -> 0.09229643 | D10: ='06_Standardized_P&L'!C12/' 07_Standardized_Balance_Sheet'!C17 -> 0.11445971 | E10: ='06_Standardized_P&L'!D12/' 07_Standardized_Balance_Sheet'!D17 -> 0.079511028 | F10: =Table3[[#This Row],[FY25]]/Table3[[#This Row],[FY23]]-1 -> -0.13852542
A11: Asset Turnover | B11: Operating Income ÷ Total Assets | C11: ='06_Standardized_P&L'!B2/' 07_Standardized_Balance_Sheet'!B14 -> 1.2635538 | D11: ='06_Standardized_P&L'!C2/' 07_Standardized_Balance_Sheet'!C14 -> 1.1809363 | E11: ='06_Standardized_P&L'!D2/' 07_Standardized_Balance_Sheet'!D14 -> 1.1894018 | F11: =Table3[[#This Row],[FY25]]/Table3[[#This Row],[FY23]]-1 -> -0.058685228
A12: Inventory Turnover | B12: Cost of Raw Materials ÷ Average Inventory | C12: =('06_Standardized_P&L'!B3*2)/((' 07_Standardized_Balance_Sheet'!B9+6294)) -> 4.3058016 | D12: =('06_Standardized_P&L'!C3*2)/((' 07_Standardized_Balance_Sheet'!C9+' 07_Standardized_Balance_Sheet'!B9)) -> 4.7405405 | E12: =('06_Standardized_P&L'!D3*2)/(' 07_Standardized_Balance_Sheet'!C9+' 07_Standardized_Balance_Sheet'!D9) -> 4.7713647 | F12: =Table3[[#This Row],[FY25]]/Table3[[#This Row],[FY23]]-1 -> 0.10812461
A13: Cash Conversion Ratio | B13: Operating Cash Flow ÷ Net Profit | C13: ='08_Standardized_Cash_Flow'!B3/'06_Standardized_P&L'!B12 -> 2.0079317 | D13: ='08_Standardized_Cash_Flow'!C3/'06_Standardized_P&L'!C12 -> 1.955889 | E13: ='08_Standardized_Cash_Flow'!D3/'06_Standardized_P&L'!D12 -> 0.83355615 | F13: =Table3[[#This Row],[FY25]]/Table3[[#This Row],[FY23]]-1 -> -0.58486827
B15: * In FY 2022 Inventory | C15: 6294

Sheet 10_Trend_Analysis
A1: Category | B1: KPI | C1: FY23 | D1: FY24 | E1: FY25 | F1: FY23–FY25 Change | G1: Trend | H1: Analyst Interpretation
A2: Income statement trends
A3: Growth | B3: Net Turnover | C3: 29109 | D3: 26596 | E3: 26183 | F3: -0.1005 | G3: Continuous decline | H3: Net turnover declined in both FY24 and FY25, indicating weaker sales performance over the three-year period.
A4: Profitability | B4: Operating Result | C4: 2246 | D4: 2339 | E4: 1725 | F4: -0.232 | G4: Peaked in FY24, then declined | H4: Operating profit improved slightly in FY24 but fell sharply in FY25, suggesting increased pressure on operating profitability.
A5: Profitability | B5: Net Profit | C5: 1639 | D5: 2199 | E5: 1496 | F5: -0.0872 | G5: Peaked in FY24, then declined | H5: Net profit reached its highest level in FY24 before falling below the FY23 level in FY25.
A6: Profitability | B6: Gross Margin | C6: 0.1816 | D6: 0.2086 | E6: 0.1854 | F6: 0.0213 | G6: Improved, then normalized | H6: Gross margin expanded in FY24 but returned close to the FY23 level in FY25 as raw-material costs increased relative to turnover.
A7: Profitability | B7: Operating Margin | C7: 0.0773 | D7: 0.0881 | E7: 0.0656 | F7: -0.1515 | G7: Peaked in FY24, then declined | H7: The FY25 decline indicates weaker operating efficiency and reduced profit generated from operating income.
A8: Profitability | B8: Net Profit Margin | C8: 0.0564 | D8: 0.0829 | E8: 0.0569 | F8: 0.008412606 | G8: Improved, then declined | H8: Net margin improved significantly in FY24 but weakened in FY25, remaining only slightly above FY23.
A9: Profitability | B9: ROA | C9: 0.0713 | D9: 0.0979 | E9: 0.0676 | F9: -0.050766318 | G9: Peaked in FY24, then declined | H9: The company generated a lower return from its asset base in FY25.
A10: Profitability | B10: ROE | C10: 0.09229643 | D10: 0.11445971 | E10: 0.079511028 | F10: -0.13852542 | G10: Peaked in FY24, then declined | H10: Returns generated on equity weakened in FY25 and fell below the FY23 level.
A12: Balance sheet and efficiency trends
A13: Liquidity | B13: Current Ratio | C13: 2.35 | D13: 3.75 | E13: 3.56 | F13: 0.5149 | G13: Improved, then moderated | H13: Short-term liquidity strengthened substantially in FY24 and remained strong in FY25 despite a slight reduction.
A14: Liquidity | B14: Quick Ratio | C14: 1.4 | D14: 2.42 | E14: 1.99 | F14: 0.422 | G14: Improved, then moderated | H14: Liquid assets remained sufficient to cover current liabilities, although liquidity weakened from the FY24 peak.
A15: Solvency | B15: Debt-to-Equity | C15: 0.3 | D15: 0.17 | E15: 0.18 | F15: -0.4056 | G15: Lower overall | H15: The reduction is favourable because it indicates lower liabilities relative to equity and less financial leverage.
A16: Solvency | B16: Equity Ratio | C16: 0.7721 | D16: 0.8549 | E16: 0.8507 | F16: 0.1019 | G16: Improved and stabilized | H16: A larger proportion of assets was financed through equity, indicating a strong capital structure.
A17: Efficiency | B17: Asset Turnover | C17: 1.26 | D17: 1.18 | E17: 1.19 | F17: -0.0587 | G17: Slight decline, then stable | H17: Asset utilization weakened slightly because operating income declined faster than the asset base.
A18: Efficiency | B18: Inventory Turnover | C18: 4.31 | D18: 4.74 | E18: 4.77 | F18: 0.1081 | G18: Gradual improvement | H18: Inventory moved more efficiently over the period, with a small further improvement in FY25.
A20: Cash-flow trends
A21: Cash Flow | B21: Operating Cash Flow | C21: 3291 | D21: 4301 | E21: 1247 | F21: -0.6211 | G21: Peaked in FY24, then fell sharply | H21: Cash generated from operations deteriorated significantly in FY25, mainly reflecting adverse working-capital movement.
A22: Cash Flow | B22: Cash Conversion Ratio | C22: 2.01 | D22: 1.96 | E22: 0.83 | F22: -0.5959 | G22: Continuous decline | H22: FY25 operating cash flow was lower than net profit, indicating weaker conversion of accounting earnings into cash.
A23: Cash Flow | B23: Investing Cash Flow | C23: -392 | D23: -256 | E23: -657 | F23: More negative | G23: Higher outflow in FY25 | H23: Investing outflows increased significantly in FY25, primarily because of higher capital expenditure.
A24: Cash Flow | B24: Financing Cash Flow | C24: -2898 | D24: -50 | E24: -1810 | F24: Volatile | G24: Significant yearly fluctuation | H24: Financing cash flows varied considerably due to changes in short-term financing, capital contributions and dividends.
A25: Cash Flow | B25: Cash at Year-End | C25: 169 | D25: 4164 | E25: 2937 | F25: 16.3787 | G25: Rose sharply, then declined | H25: Cash remained substantially above FY23, although the balance declined in FY25 following negative net cash flow.
A29: Overall Three-Year Financial Trend
A31: Inter IKEA Group experienced declining net turnover between FY23 and FY25. Profitability improved in FY24 but weakened materially in FY25, as reflected in lower operating margin, ROA and ROE. The balance sheet remained financially strong, supported by high liquidity, a reduced debt-to-equity ratio and a high equity ratio. Inventory turnover improved gradually, although asset utilization remained slightly below FY23. The most significant concern was the sharp reduction in operating cash flow and cash conversion during FY25, indicating weaker conversion of reported earnings into cash.

Sheet 11_Dashboard_Data
A1: Section 1 – Executive KPI Cards
A3: KPI | B3: FY23 | C3: FY24 | D3: FY25 | E3: 3-Year Change
A4: Revenue (€M) | B4: 29109 | C4: 26596 | D4: 26183 | E4: -0.1005
A5: Operating Profit (€M) | B5: 2246 | C5: 2339 | D5: 1725 | E5: -0.232
A6: Net Profit (€M) | B6: 1639 | C6: 2199 | D6: 1496 | E6: -0.0872
A7: Current Ratio | B7: 2.35 | C7: 3.75 | D7: 3.56 | E7: 0.5149
A8: ROE | B8: 0.0923 | C8: 0.1145 | D8: 0.0795 | E8: -0.13852542
A9: Operating Cash Flow (€M) | B9: 3291 | C9: 4301 | D9: 1247 | E9: -0.6211
A12: Section 2 – Revenue & Profit Trend
A14: Year | B14: Revenue | C14: Operating Profit | D14: Net Profit
A15: FY23 | B15: 29109 | C15: 2246 | D15: 1639
A16: FY24 | B16: 26596 | C16: 2339 | D16: 2199
A17: FY25 | B17: 26183 | C17: 1725 | D17: 1496
A19: Section 3 – Profitability Trend
A21: Year | B21: Gross Margin | C21: Operating Margin | D21: Net Profit Margin
A22: FY23 | B22: 0.1816 | C22: 0.0773 | D22: 0.0564
A23: FY24 | B23: 0.2086 | C23: 0.0881 | D23: 0.0829
A24: FY25 | B24: 0.1854 | C24: 0.0656 | D24: 0.0569
A26: Section 4 – Liquidity
A28: Year | B28: Current Ratio | C28: Quick Ratio
A29: FY23 | B29: 2.35 | C29: 1.4
A30: FY24 | B30: 3.75 | C30: 2.42
A31: FY25 | B31: 3.56 | C31: 1.99
A33: Section 5 – Solvency
A35: Year | B35: Debt-to-Equity | C35: Equity Ratio
A36: FY23 | B36: 0.3 | C36: 0.7721
A37: FY24 | B37: 0.17 | C37: 0.8549
A38: FY25 | B38: 0.18 | C38: 0.8507
A40: Section 6 – Efficiency
A42: Year | B42: Asset Turnover | C42: Inventory Turnover
A43: FY23 | B43: 1.26 | C43: 4.31
A44: FY24 | B44: 1.18 | C44: 4.74
A45: FY25 | B45: 1.19 | C45: 4.77
A47: Section 7 – Cash Flow
A49: Year | B49: Operating CF | C49: Investing CF | D49: Financing CF
A50: FY23 | B50: 3291 | C50: -392 | D50: -2898
A51: FY24 | B51: 4301 | C51: -256 | D51: -50
A52: FY25 | B52: 1247 | C52: -657 | D52: -1810
A54: Section 8 – Return Ratios
A56: Year | B56: ROA | C56: ROE
...

Sheet 12_Dashboard
B2: INTER IKEA GROUP FINANCIAL STATEMENT ANALYSIS | FY23–FY25
B4: Amounts in € million unless otherwise stated
B6: REVENUE | D6: OPERATING PROFIT | F6: NET PROFIT | H6: CURRENT RATIO | J6: ROE | L6: OPERATING CASH FLOW
B7: €26.18B | D7: €1.73B | F7: €1.50B | H7: 3.56x | J7: 0.0795 | L7: €1.25B
B10: ▼ 10.05% vs FY23 | D10: ▼ 23.20% vs FY23 | F10: ▼ 8.72% vs FY23 | H10: ▲ 51.49% vs FY23 | J10: ▼ 13.85% vs FY23 | L10: ▼ 62.11% vs FY23
C67: KEY FINANCIAL INSIGHTS
C68: Revenue declined by 10.5% from FY23 to FY25, indicating softer top-line performance.
C69: Operating profit declined by 23.2%, while net profit declined by 8.7% over the three-year period.
C70: Liquidity remained strong in FY25, with a current ratio of 3.56x and a quick ratio of 1.99x.
C71: FY25 operating cash flow fell to €1.25B, down 62.1% versus FY23.
C72: Capital structure remained conservative: debt-to-equity was 0.18x and the equity ratio was 85.1% in FY25.
C73: Operating efficiency was mixed: inventory turnover improved to 4.77x, while asset turnover was 1.19x.
C76: Source: Inter IKEA Group Annual Reports FY23–FY25 | Dashboard linked to 11_Dashboard_Data
